Workbook

Sheet Simulador
B2: Simulador de Investimentos em Fundos Imobiliários (FIIs) | E2: Legenda
B3: Preencha as células em amarelo com os dados da sua simulação | E3: Amarelo + azul = célula de entrada (edite aqui)
E4: Azul claro = resultado calculado automaticamente
B5: PARÂMETROS DA SIMULAÇÃO | E5: Aba 'Evolução Mensal' mostra o detalhamento mês a mês
B6: Valor Inicial Investido | C6: 10000
B7: Aporte Mensal | C7: 500
B8: Taxa de Rendimento Mensal (%) | C8: 0.008
B9: Prazo da Simulação (meses) | C9: 60
B10: Reinvestir Dividendos? (Sim/Não) | C10: Sim
B12: RESULTADO DA SIMULAÇÃO
B13: Total Investido (aportes) | C13: =C6+C7*C9 -> 40000
B14: Patrimônio Acumulado ao Final do Prazo | C14: =INDEX('Evolução Mensal'!F:F,MATCH(C9,'Evolução Mensal'!A:A,0)) -> 54441.843
B15: Total de Dividendos Recebidos no Período | C15: =INDEX('Evolução Mensal'!G:G,MATCH(C9,'Evolução Mensal'!A:A,0)) -> 14441.843
B16: Saldo em Caixa (dividendos não reinvestidos) | C16: =INDEX('Evolução Mensal'!H:H,MATCH(C9,'Evolução Mensal'!A:A,0)) -> 0
B17: Retorno Total sobre o Investido (%) | C17: =(C14+C16-C13)/C13 -> 0.36104607
B19: Fonte: valores de entrada informados pelo usuário; fórmulas calculadas automaticamente.

Sheet Evolução Mensal
A1: Mês | B1: Patrimônio no Início do Mês (R$) | C1: Aporte do Mês (R$) | D1: Dividendo do Mês (R$) | E1: Reinvestimento do Mês (R$) | F1: Patrimônio no Final do Mês (R$) | G1: Dividendos Acumulados (R$) | H1: Caixa Acumulado - Não Reinvestido (R$) | I1: Total Investido Acumulado (R$)
A2: 1 | B2: =Simulador!C6 -> 10000 | C2: =Simulador!C7 -> 500 | D2: =B2*Simulador!C8 -> 80 | E2: =IF(Simulador!C10="Sim",D2,0) -> 80 | F2: =B2+C2+E2 -> 10580 | G2: =D2 -> 80 | H2: =IF(Simulador!C10="Não",D2,0) -> 0 | I2: =Simulador!C6+C2 -> 10500
A3: 2 | B3: =F2 -> 10580 | C3: =Simulador!C7 -> 500 | D3: =B3*Simulador!C8 -> 84.64 | E3: =IF(Simulador!C10="Sim",D3,0) -> 84.64 | F3: =B3+C3+E3 -> 11164.64 | G3: =G2+D3 -> 164.64 | H3: =H2+IF(Simulador!C10="Não",D3,0) -> 0 | I3: =I2+C3 -> 11000
A4: 3 | B4: =F3 -> 11164.64 | C4: =Simulador!C7 -> 500 | D4: =B4*Simulador!C8 -> 89.31712 | E4: =IF(Simulador!C10="Sim",D4,0) -> 89.31712 | F4: =B4+C4+E4 -> 11753.957 | G4: =G3+D4 -> 253.95712 | H4: =H3+IF(Simulador!C10="Não",D4,0) -> 0 | I4: =I3+C4 -> 11500
A5: 4 | B5: =F4 -> 11753.957 | C5: =Simulador!C7 -> 500 | D5: =B5*Simulador!C8 -> 94.031657 | E5: =IF(Simulador!C10="Sim",D5,0) -> 94.031657 | F5: =B5+C5+E5 -> 12347.989 | G5: =G4+D5 -> 347.98878 | H5: =H4+IF(Simulador!C10="Não",D5,0) -> 0 | I5: =I4+C5 -> 12000
A6: 5 | B6: =F5 -> 12347.989 | C6: =Simulador!C7 -> 500 | D6: =B6*Simulador!C8 -> 98.78391 | E6: =IF(Simulador!C10="Sim",D6,0) -> 98.78391 | F6: =B6+C6+E6 -> 12946.773 | G6: =G5+D6 -> 446.77269 | H6: =H5+IF(Simulador!C10="Não",D6,0) -> 0 | I6: =I5+C6 -> 12500
A7: 6 | B7: =F6 -> 12946.773 | C7: =Simulador!C7 -> 500 | D7: =B7*Simulador!C8 -> 103.57418 | E7: =IF(Simulador!C10="Sim",D7,0) -> 103.57418 | F7: =B7+C7+E7 -> 13550.347 | G7: =G6+D7 -> 550.34687 | H7: =H6+IF(Simulador!C10="Não",D7,0) -> 0 | I7: =I6+C7 -> 13000
A8: 7 | B8: =F7 -> 13550.347 | C8: =Simulador!C7 -> 500 | D8: =B8*Simulador!C8 -> 108.40277 | E8: =IF(Simulador!C10="Sim",D8,0) -> 108.40277 | F8: =B8+C8+E8 -> 14158.75 | G8: =G7+D8 -> 658.74964 | H8: =H7+IF(Simulador!C10="Não",D8,0) -> 0 | I8: =I7+C8 -> 13500
A9: 8 | B9: =F8 -> 14158.75 | C9: =Simulador!C7 -> 500 | D9: =B9*Simulador!C8 -> 113.27 | E9: =IF(Simulador!C10="Sim",D9,0) -> 113.27 | F9: =B9+C9+E9 -> 14772.02 | G9: =G8+D9 -> 772.01964 | H9: =H8+IF(Simulador!C10="Não",D9,0) -> 0 | I9: =I8+C9 -> 14000
A10: 9 | B10: =F9 -> 14772.02 | C10: =Simulador!C7 -> 500 | D10: =B10*Simulador!C8 -> 118.17616 | E10: =IF(Simulador!C10="Sim",D10,0) -> 118.17616 | F10: =B10+C10+E10 -> 15390.196 | G10: =G9+D10 -> 890.1958 | H10: =H9+IF(Simulador!C10="Não",D10,0) -> 0 | I10: =I9+C10 -> 14500
A11: 10 | B11: =F10 -> 15390.196 | C11: =Simulador!C7 -> 500 | D11: =B11*Simulador!C8 -> 123.12157 | E11: =IF(Simulador!C10="Sim",D11,0) -> 123.12157 | F11: =B11+C11+E11 -> 16013.317 | G11: =G10+D11 -> 1013.3174 | H11: =H10+IF(Simulador!C10="Não",D11,0) -> 0 | I11: =I10+C11 -> 15000
A12: 11 | B12: =F11 -> 16013.317 | C12: =Simulador!C7 -> 500 | D12: =B12*Simulador!C8 -> 128.10654 | E12: =IF(Simulador!C10="Sim",D12,0) -> 128.10654 | F12: =B12+C12+E12 -> 16641.424 | G12: =G11+D12 -> 1141.4239 | H12: =H11+IF(Simulador!C10="Não",D12,0) -> 0 | I12: =I11+C12 -> 15500
A13: 12 | B13: =F12 -> 16641.424 | C13: =Simulador!C7 -> 500 | D13: =B13*Simulador!C8 -> 133.13139 | E13: =IF(Simulador!C10="Sim",D13,0) -> 133.13139 | F13: =B13+C13+E13 -> 17274.555 | G13: =G12+D13 -> 1274.5553 | H13: =H12+IF(Simulador!C10="Não",D13,0) -> 0 | I13: =I12+C13 -> 16000
A14: 13 | B14: =F13 -> 17274.555 | C14: =Simulador!C7 -> 500 | D14: =B14*Simulador!C8 -> 138.19644 | E14: =IF(Simulador!C10="Sim",D14,0) -> 138.19644 | F14: =B14+C14+E14 -> 17912.752 | G14: =G13+D14 -> 1412.7517 | H14: =H13+IF(Simulador!C10="Não",D14,0) -> 0 | I14: =I13+C14 -> 16500
A15: 14 | B15: =F14 -> 17912.752 | C15: =Simulador!C7 -> 500 | D15: =B15*Simulador!C8 -> 143.30201 | E15: =IF(Simulador!C10="Sim",D15,0) -> 143.30201 | F15: =B15+C15+E15 -> 18556.054 | G15: =G14+D15 -> 1556.0538 | H15: =H14+IF(Simulador!C10="Não",D15,0) -> 0 | I15: =I14+C15 -> 17000
A16: 15 | B16: =F15 -> 18556.054 | C16: =Simulador!C7 -> 500 | D16: =B16*Simulador!C8 -> 148.44843 | E16: =IF(Simulador!C10="Sim",D16,0) -> 148.44843 | F16: =B16+C16+E16 -> 19204.502 | G16: =G15+D16 -> 1704.5022 | H16: =H15+IF(Simulador!C10="Não",D16,0) -> 0 | I16: =I15+C16 -> 17500
A17: 16 | B17: =F16 -> 19204.502 | C17: =Simulador!C7 -> 500 | D17: =B17*Simulador!C8 -> 153.63602 | E17: =IF(Simulador!C10="Sim",D17,0) -> 153.63602 | F17: =B17+C17+E17 -> 19858.138 | G17: =G16+D17 -> 1858.1382 | H17: =H16+IF(Simulador!C10="Não",D17,0) -> 0 | I17: =I16+C17 -> 18000
A18: 17 | B18: =F17 -> 19858.138 | C18: =Simulador!C7 -> 500 | D18: =B18*Simulador!C8 -> 158.86511 | E18: =IF(Simulador!C10="Sim",D18,0) -> 158.86511 | F18: =B18+C18+E18 -> 20517.003 | G18: =G17+D18 -> 2017.0033 | H18: =H17+IF(Simulador!C10="Não",D18,0) -> 0 | I18: =I17+C18 -> 18500
A19: 18 | B19: =F18 -> 20517.003 | C19: =Simulador!C7 -> 500 | D19: =B19*Simulador!C8 -> 164.13603 | E19: =IF(Simulador!C10="Sim",D19,0) -> 164.13603 | F19: =B19+C19+E19 -> 21181.139 | G19: =G18+D19 -> 2181.1393 | H19: =H18+IF(Simulador!C10="Não",D19,0) -> 0 | I19: =I18+C19 -> 19000
A20: 19 | B20: =F19 -> 21181.139 | C20: =Simulador!C7 -> 500 | D20: =B20*Simulador!C8 -> 169.44911 | E20: =IF(Simulador!C10="Sim",D20,0) -> 169.44911 | F20: =B20+C20+E20 -> 21850.588 | G20: =G19+D20 -> 2350.5884 | H20: =H19+IF(Simulador!C10="Não",D20,0) -> 0 | I20: =I19+C20 -> 19500
A21: 20 | B21: =F20 -> 21850.588 | C21: =Simulador!C7 -> 500 | D21: =B21*Simulador!C8 -> 174.80471 | E21: =IF(Simulador!C10="Sim",D21,0) -> 174.80471 | F21: =B21+C21+E21 -> 22525.393 | G21: =G20+D21 -> 2525.3932 | H21: =H20+IF(Simulador!C10="Não",D21,0) -> 0 | I21: =I20+C21 -> 20000
A22: 21 | B22: =F21 -> 22525.393 | C22: =Simulador!C7 -> 500 | D22: =B22*Simulador!C8 -> 180.20315 | E22: =IF(Simulador!C10="Sim",D22,0) -> 180.20315 | F22: =B22+C22+E22 -> 23205.596 | G22: =G21+D22 -> 2705.5963 | H22: =H21+IF(Simulador!C10="Não",D22,0) -> 0 | I22: =I21+C22 -> 20500
A23: 22 | B23: =F22 -> 23205.596 | C23: =Simulador!C7 -> 500 | D23: =B23*Simulador!C8 -> 185.64477 | E23: =IF(Simulador!C10="Sim",D23,0) -> 185.64477 | F23: =B23+C23+E23 -> 23891.241 | G23: =G22+D23 -> 2891.2411 | H23: =H22+IF(Simulador!C10="Não",D23,0) -> 0 | I23: =I22+C23 -> 21000
A24: 23 | B24: =F23 -> 23891.241 | C24: =Simulador!C7 -> 500 | D24: =B24*Simulador!C8 -> 191.12993 | E24: =IF(Simulador!C10="Sim",D24,0) -> 191.12993 | F24: =B24+C24+E24 -> 24582.371 | G24: =G23+D24 -> 3082.371 | H24: =H23+IF(Simulador!C10="Não",D24,0) -> 0 | I24: =I23+C24 -> 21500
A25: 24 | B25: =F24 -> 24582.371 | C25: =Simulador!C7 -> 500 | D25: =B25*Simulador!C8 -> 196.65897 | E25: =IF(Simulador!C10="Sim",D25,0) -> 196.65897 | F25: =B25+C25+E25 -> 25279.03 | G25: =G24+D25 -> 3279.03 | H25: =H24+IF(Simulador!C10="Não",D25,0) -> 0 | I25: =I24+C25 -> 22000
A26: 25 | B26: =F25 -> 25279.03 | C26: =Simulador!C7 -> 500 | D26: =B26*Simulador!C8 -> 202.23224 | E26: =IF(Simulador!C10="Sim",D26,0) -> 202.23224 | F26: =B26+C26+E26 -> 25981.262 | G26: =G25+D26 -> 3481.2622 | H26: =H25+IF(Simulador!C10="Não",D26,0) -> 0 | I26: =I25+C26 -> 22500
A27: 26 | B27: =F26 -> 25981.262 | C27: =Simulador!C7 -> 500 | D27: =B27*Simulador!C8 -> 207.8501 | E27: =IF(Simulador!C10="Sim",D27,0) -> 207.8501 | F27: =B27+C27+E27 -> 26689.112 | G27: =G26+D27 -> 3689.1123 | H27: =H26+IF(Simulador!C10="Não",D27,0) -> 0 | I27: =I26+C27 -> 23000
A28: 27 | B28: =F27 -> 26689.112 | C28: =Simulador!C7 -> 500 | D28: =B28*Simulador!C8 -> 213.5129 | E28: =IF(Simulador!C10="Sim",D28,0) -> 213.5129 | F28: =B28+C28+E28 -> 27402.625 | G28: =G27+D28 -> 3902.6252 | H28: =H27+IF(Simulador!C10="Não",D28,0) -> 0 | I28: =I27+C28 -> 23500
A29: 28 | B29: =F28 -> 27402.625 | C29: =Simulador!C7 -> 500 | D29: =B29*Simulador!C8 -> 219.221 | E29: =IF(Simulador!C10="Sim",D29,0) -> 219.221 | F29: =B29+C29+E29 -> 28121.846 | G29: =G28+D29 -> 4121.8462 | H29: =H28+IF(Simulador!C10="Não",D29,0) -> 0 | I29: =I28+C29 -> 24000
A30: 29 | B30: =F29 -> 28121.846 | C30: =Simulador!C7 -> 500 | D30: =B30*Simulador!C8 -> 224.97477 | E30: =IF(Simulador!C10="Sim",D30,0) -> 224.97477 | F30: =B30+C30+E30 -> 28846.821 | G30: =G29+D30 -> 4346.821 | H30: =H29+IF(Simulador!C10="Não",D30,0) -> 0 | I30: =I29+C30 -> 24500
A31: 30 | B31: =F30 -> 28846.821 | C31: =Simulador!C7 -> 500 | D31: =B31*Simulador!C8 -> 230.77457 | E31: =IF(Simulador!C10="Sim",D31,0) -> 230.77457 | F31: =B31+C31+E31 -> 29577.596 | G31: =G30+D31 -> 4577.5955 | H31: =H30+IF(Simulador!C10="Não",D31,0) -> 0 | I31: =I30+C31 -> 25000
A32: 31 | B32: =F31 -> 29577.596 | C32: =Simulador!C7 -> 500 | D32: =B32*Simulador!C8 -> 236.62076 | E32: =IF(Simulador!C10="Sim",D32,0) -> 236.62076 | F32: =B32+C32+E32 -> 30314.216 | G32: =G31+D32 -> 4814.2163 | H32: =H31+IF(Simulador!C10="Não",D32,0) -> 0 | I32: =I31+C32 -> 25500
A33: 32 | B33: =F32 -> 30314.216 | C33: =Simulador!C7 -> 500 | D33: =B33*Simulador!C8 -> 242.51373 | E33: =IF(Simulador!C10="Sim",D33,0) -> 242.51373 | F33: =B33+C33+E33 -> 31056.73 | G33: =G32+D33 -> 5056.73 | H33: =H32+IF(Simulador!C10="Não",D33,0) -> 0 | I33: =I32+C33 -> 26000
A34: 33 | B34: =F33 -> 31056.73 | C34: =Simulador!C7 -> 500 | D34: =B34*Simulador!C8 -> 248.45384 | E34: =IF(Simulador!C10="Sim",D34,0) -> 248.45384 | F34: =B34+C34+E34 -> 31805.184 | G34: =G33+D34 -> 5305.1839 | H34: =H33+IF(Simulador!C10="Não",D34,0) -> 0 | I34: =I33+C34 -> 26500
A35: 34 | B35: =F34 -> 31805.184 | C35: =Simulador!C7 -> 500 | D35: =B35*Simulador!C8 -> 254.44147 | E35: =IF(Simulador!C10="Sim",D35,0) -> 254.44147 | F35: =B35+C35+E35 -> 32559.625 | G35: =G34+D35 -> 5559.6253 | H35: =H34+IF(Simulador!C10="Não",D35,0) -> 0 | I35: =I34+C35 -> 27000
A36: 35 | B36: =F35 -> 32559.625 | C36: =Simulador!C7 -> 500 | D36: =B36*Simulador!C8 -> 260.477 | E36: =IF(Simulador!C10="Sim",D36,0) -> 260.477 | F36: =B36+C36+E36 -> 33320.102 | G36: =G35+D36 -> 5820.1023 | H36: =H35+IF(Simulador!C10="Não",D36,0) -> 0 | I36: =I35+C36 -> 27500
A37: 36 | B37: =F36 -> 33320.102 | C37: =Simulador!C7 -> 500 | D37: =B37*Simulador!C8 -> 266.56082 | E37: =IF(Simulador!C10="Sim",D37,0) -> 266.56082 | F37: =B37+C37+E37 -> 34086.663 | G37: =G36+D37 -> 6086.6632 | H37: =H36+IF(Simulador!C10="Não",D37,0) -> 0 | I37: =I36+C37 -> 28000
A38: 37 | B38: =F37 -> 34086.663 | C38: =Simulador!C7 -> 500 | D38: =B38*Simulador!C8 -> 272.69331 | E38: =IF(Simulador!C10="Sim",D38,0) -> 272.69331 | F38: =B38+C38+E38 -> 34859.356 | G38: =G37+D38 -> 6359.3565 | H38: =H37+IF(Simulador!C10="Não",D38,0) -> 0 | I38: =I37+C38 -> 28500
A39: 38 | B39: =F38 -> 34859.356 | C39: =Simulador!C7 -> 500 | D39: =B39*Simulador!C8 -> 278.87485 | E39: =IF(Simulador!C10="Sim",D39,0) -> 278.87485 | F39: =B39+C39+E39 -> 35638.231 | G39: =G38+D39 -> 6638.2313 | H39: =H38+IF(Simulador!C10="Não",D39,0) -> 0 | I39: =I38+C39 -> 29000
A40: 39 | B40: =F39 -> 35638.231 | C40: =Simulador!C7 -> 500 | D40: =B40*Simulador!C8 -> 285.10585 | E40: =IF(Simulador!C10="Sim",D40,0) -> 285.10585 | F40: =B40+C40+E40 -> 36423.337 | G40: =G39+D40 -> 6923.3372 | H40: =H39+IF(Simulador!C10="Não",D40,0) -> 0 | I40: =I39+C40 -> 29500
...
